Workbook

Sheet Read Me
A1: esp_watch - BOM & Power Budget
A3: Updated | B3: 3 Oct 2026. Rebuilt for the board as built: XIAO ESP32-C3 carrier PCB with off-the-shelf modules. Replaces the earlier version, which modelled a bare ESP32-C3-MINI board with its own LDO, charger, protection and battery divider. None of those parts are on esp_watch.
A4: Design basis | B4: Seeed Studio XIAO ESP32-C3 (onboard charger, 3.3 V regulator, USB-C, U.FL antenna) on a 37.8 x 39 mm 2-layer carrier PCB. No discrete ICs.
A5: Sensors / display | B5: MAX30102 black module (underside, on SMD pads), MPU-6050 module (GY-521 clone), SSD1306 0.96in 128x64 OLED on a female header. One I2C bus on D4 (SDA) / D5 (SCL), using the modules' own pull-ups; no resistors on the carrier.
A6: Battery | B6: Protected 3.7 V LiPo, 300 mAh, 30 x 12 x 4 mm, off-board, through slide switch SW3 to the XIAO BAT pads. SW3 pads are on the board; the switch is not yet fitted.
A7: Firmware today | B7: Always on: no sleep mode and no shake-to-wake. WiFi connects once at switch-on (IST time, Open-Meteo weather), then stays off. Sensors are polled; no interrupts.
A8: How to use | B8: Blue cells are inputs you can change. Black cells are formulas. Green cells pull from another sheet. Yellow cells are still to be filled in. Edit currents on 'Power Budget' and hours or battery size on 'Runtime'; everything else recalculates.
A9: Price basis | B9: Module prices are EXAMPLE values from Robu listings checked 24 Sep 2026, INR including GST. They are not the author's purchase prices. Recorded actuals: green MAX30102 module Rs 265; JLCPCB order $18.68 paid for 5 boards.
A10: Caution | B10: Every current here is MODELLED from datasheets and Seeed's published figures. No current has been measured on esp_watch. Sleep rows describe a PLANNED firmware profile, not today's firmware.
A12: Sheets
A13: BOM | B13: Bill of materials for one board, with example prices and the PCB order.
A14: Alternates | B14: Substitutes if a part is unavailable or obsolete, and what each changes.
A15: Pin Map | B15: XIAO ESP32-C3 pin assignment as built.
A16: Power Budget | B16: Modelled current of each block in each state.
A17: Runtime | B17: Current per state, daily charge and battery life for today's firmware and the planned profile.

Sheet BOM
A1: # | B1: Ref | C1: Qty | D1: Description | E1: Manufacturer | F1: Part / variant | G1: Mounting | H1: Supplier (example) | I1: Unit INR | J1: Ext INR | K1: Notes
A2: 1 | B2: U1 | C2: 1 | D2: MCU board: ESP32-C3, WiFi + BLE 5, 4 MB flash, onboard LiPo charger, 3.3 V regulator, USB-C, U.FL antenna supplied | E2: Seeed Studio | F2: XIAO ESP32C3 | G2: Top side, castellated / header | H2: Robu | I2: 849 | J2: =IF(I2="","",C2*I2) -> 849 | K2: Robu Rs 849 incl. GST, out of stock (24 Sep 2026). External antenna on U.FL: no copper under it, keep it away from the battery.
A3: 2 | B3: U2 | C3: 1 | D3: Heart-rate / SpO2 sensor module, MAX30102, BLACK (3.3 V I2C) | E3: Generic | F3: MAX30102 module, black | G3: Bottom side, 8 SMD pads (MAX30102_module footprint) | H3: Robu | I3: 179 | J3: =IF(I3="","",C3*I3) -> 179 | K3: Robu Rs 179 incl. GST, out of stock (24 Sep 2026). Use the black module: the green one's pull-ups go to 1.8 V and clamped the shared bus (measured). Green module bought by the author: Rs 265 (recorded, not used).
A4: 3 | B4: U3 | C4: 1 | D4: 6-axis IMU module, MPU-6050 (GY-521 style), AD0 to GND, I2C 0x68 | E4: Generic (clone) | F4: GY-521 MPU-6050 | G4: Top side, header | H4: Robu | I4: 159 | J4: =IF(I4="","",C4*I4) -> 159 | K4: Robu Rs 159 incl. GST, out of stock (24 Sep 2026). Clone: WHO_AM_I reads 0x70, works correctly. MPU-6050 chip is obsolete - see Alternates.
A5: 4 | B5: U4 | C5: 1 | D5: OLED 0.96in 128x64, SSD1306, I2C 0x3C, 4-pin module, white | E5: Generic | F5: SSD1306 0.96in 4-pin | G5: Top side, on female header above the MPU | H5: Robu | I5: 229 | J5: =IF(I5="","",C5*I5) -> 229 | K5: Robu Rs 229 incl. GST, in stock (24 Sep 2026).
A6: 5 | B6: J1 | C6: 1 | D6: Female header, 4-pin 2.54 mm, for the OLED | E6: Generic | F6: 1x4 female header, 2.54 mm | G6: Top side, THT | H6: comes along oled display | I6: 0 | J6: =IF(I6="","",C6*I6) -> 0 | K6: OLED sits on it with a 4-5 mm gap above the MPU. Price not recorded.
A7: 6 | B7: SW1, SW2 | C7: 2 | D7: Tactile pushbutton, "next" (GPIO10) and "previous" (GPIO3) | E7: Generic | F7: SW_Push (THT) | G7: Top side, THT | H7: robu | I7: 19 | J7: =IF(I7="","",C7*I7) -> 38 | K7: To GND; firmware uses the ESP32-C3 internal pull-ups. Price not recorded.
A8: 7 | B8: SW3 | C8: 1 | D8: Slide switch in the battery line | E8: Wurth Elektronik | F8: WS-SLTV 450301014042 | G8: Top side, THT (SW_Slide-03_Wuerth-WS-SLTV_10x2.5x6.4_P2.54mm) | H8: robu | I8: 22 | J8: =IF(I8="","",C8*I8) -> 22 | K8: Pads on the board; switch not yet fitted or tested. Price not recorded.
A9: 8 | B9: BT1 | C9: 1 | D9: LiPo cell 3.7 V, 300 mAh, 30 x 12 x 4 mm, PROTECTED (own protection circuit) | E9: Generic | F9: 300 mAh 30x12x4 mm | G9: Off-board, wired to XIAO BAT+/BAT- via SW3 | H9: robu | I9: 299 | J9: =IF(I9="","",C9*I9) -> 299 | K9: 3.7 V cell only on the BAT pads, never 5 V. The XIAO charges it from USB-C. Price not recorded.
H10: https://www.amazon.in/dp/B0HC9TDL43?ref=ppx_yo2ov_dt_b_fed_asin_title
H11: Subtotal, priced lines (INR) | J11: =SUM(J2:J9) -> 1775
H12: Lines still to price | J12: =COUNTBLANK(I2:I9) -> 0 | K12: Yellow cells: add a dated example price (F0 does this at three quantities).
A14: PCB order (recorded, JLCPCB quote screenshot asset/pcb/JLCPCB_quote.png)
H15: Boards ordered | J15: 5 | K15: 2-layer, 37.8 x 39 mm (JLCPCB quote page).
H16: Fabrication (USD) | J16: 4
H17: Shipping, DHL Express (USD) | J17: 24.68 | K17: Quoted 2-day build, 2-5 business days shipping.
H18: Discount (USD) | J18: -10
H19: Paid (USD) | J19: =SUM(J16:J18) -> 18.68 | K19: Customs / GST on import: not recorded.
H20: Per board (USD) | J20: =IF(J15=0,"",J19/J15) -> 3.736
H21: USD to INR rate | J21: 1796 | K21: Enter the rate on the day you cost it; the two INR lines below fill in.
H22: Per board (INR) | J22: =IF(J21="","",J20*J21) -> 6709.856
H23: Cost per board, parts + PCB (INR) | J23: =IF(J22="","",J11+J22) -> 8484.856 | K23: Priced lines only, before shipping on the parts. Incomplete until every yellow cell is filled.
H24: custom duty | J24: 1856 | K24: custom duty paid at india

Sheet Alternates
A1: Function | B1: Used on esp_watch | C1: Alternate | D1: Why / when to switch | E1: Board / firmware impact
A2: MCU board | B2: XIAO ESP32C3 | C2: XIAO ESP32S3 / XIAO ESP32C6 | D2: Same XIAO footprint and pin labels. S3: more RAM and pins; C6: adds 802.15.4 (Thread/Zigbee). | E2: Footprint unchanged. Check the GPIO behind each D-label, then rebuild the firmware for the new chip.
A3: Heart rate | B3: MAX30102 module, black | C3: MAX30102 module, green | D3: Cheaper and common, but its I2C pull-ups go to 1.8 V. On the shared bus it clamped idle to 1.82 V and 80% of MPU reads failed (measured). | E3: Only usable with its pull-ups removed or on its own bus. Not recommended.
A4: Heart rate | B4: MAX30102 | C4: MAX30101 module | D4: Adds a green LED, which works better for wrist readings during movement. | E4: Same register map; enable the green LED slot. Check the module's footprint.
A5: IMU | B5: MPU-6050 (obsolete, ~3.9 mA running) | C5: LSM6DS3TR-C module | D5: In production, hardware pedometer, about 26 uA in low-power mode. | E5: New driver; can use the chip's step counter. New footprint if the module differs.
A6: IMU | B6: MPU-6050 | C6: LIS2DH12 / BMA400 accelerometer module | D6: Accelerometer only, a few uA. Enough for steps if no gyro is needed. | E6: New accel driver; step algorithm kept.
A7: IMU | B7: MPU-6050 | C7: MPU-6500 module | D7: Closest upgrade from the same family, lower current. | E7: Minor register changes; WHO_AM_I differs.
A8: Display | B8: SSD1306 0.96in module | C8: SH1106 1.3in module | D8: Larger and easier to read, same 128x64 and I2C. | E8: Different driver (SH1106 library); bigger module, so the board outline and case change.
A9: Display | B9: SSD1306 module | C9: Bare 0.96in panel + FPC connector | D9: Thinner, looks like a product. Needs the panel's support capacitors on the carrier. | E9: Same SSD1306 driver; new footprint and parts on the carrier.
A10: Battery | B10: 300 mAh, 30 x 12 x 4 mm | C10: 301235 (~100 mAh) / 401235 (~150 mAh) / 501235 (~200 mAh) | D10: Earlier candidates: smaller and thinner, shorter runtime (see Runtime, cell comparison). | E10: Case cavity changes. Must still be a protected cell.
A11: Battery level | B11: (none: no battery reading) | C11: Divider to an ADC1 pin, or MAX17048 fuel gauge | D11: esp_watch cannot show battery level. A divider is cheapest; a gauge gives real percentage. | E11: Divider: two resistors and an ADC1 pin (not ADC2). Gauge: one more I2C device.
A12: Power switch | B12: Wurth WS-SLTV 450301014042 | C12: Any SPDT slide switch on 2.54 mm pitch | D12: If the Wurth part is out of stock. | E12: Check the footprint and the case cut-out.

Sheet Pin Map
A1: Signal | B1: XIAO label | C1: Symbol pin | D1: Direction | E1: Notes
A2: I2C SDA | B2: D4 | C2: 5 | D2: bidir | E2: Shared by OLED 0x3C, MPU-6050 0x68, MAX30102 0x57. Pull-ups: the modules' own, left fitted (three pairs in parallel, about 1.5 kOhm). No resistors on the carrier.
A3: I2C SCL | B3: D5 | C3: 6 | D3: out | E3: Same bus. Tested at 100 kHz and 400 kHz with the black MAX module.
A4: Button "next" | B4: D10 | C4: 11 | D4: in, pull-up | E4: To GND, internal pull-up.
A5: Button "previous" | B5: D9 | C5: 10 | D5: in, pull-up | E5: To GND, internal pull-up. Shares the pin with the XIAO's BOOT button: unpressed, the watch starts normally; held during reset, it starts in download mode.
A6: (unconnected) | B6: D0 | C6: 1 | D6: - | E6: Strapping pin, must be high at reset. Left free.
A7: (unconnected) | B7: D1, D2, D3 | C7: 2, 3, 4 | D7: - | E7: No sensor interrupts and no battery sense. D1 and D2 are ADC1 pins, free for a battery divider in a v2.
A8: (unconnected) | B8: D6, D7 | C8: 7, 8 | D8: - | E8: UART TX / RX, left free for debugging.
A9: (unconnected) | B9: D8 | C9: 9 | D9: - | E9: Strapping pin, must be high at reset. Left free.
A10: 3.3 V rail | B10: 3V3 | C10: 12 | D10: power out | E10: Feeds OLED, IMU and MAX30102. XIAO regulator.
A11: Ground | B11: GND | C11: 13 | D11: power
A12: Battery | B12: BAT+ / BAT- | C12: B+ / B- | D12: power | E12: Protected 3.7 V LiPo through SW3 (pads fitted, switch not yet).
A13: USB | B13: USB-C | C13: - | D13: USB | E13: Programming, serial and charging, on the XIAO itself. Port faces the left of the watch.
A15: Interrupts | E15: None used. The firmware polls both sensors over I2C.

Sheet Power Budget
A1: Block | B1: Operating state | C1: Current (mA) | D1: Basis / source
A2: ESP32-C3 | B2: CPU active, RF off | C2: 22 | D2: Espressif datasheet, CPU running with radio off (20-25 mA typical). Today's loop also waits in delay(), so the real figure may be lower: measure it.
A3: ESP32-C3 | B3: WiFi connected, idle (modem-sleep avg) | C3: 20 | D3: Espressif datasheet, DTIM modem-sleep average.
A4: ESP32-C3 | B4: WiFi connected + traffic (avg) | C4: 100 | D4: Average over TX/RX bursts; peaks about 350 mA. Time + weather fetch at switch-on only.
A5: XIAO ESP32-C3 board | B5: Deep sleep | C5: 0.043 | D5: REFERENCE-PRODUCT section 4 (Seeed published, about 43 uA; Seeed wiki lists about 44 uA). Not used by today's firmware.
A6: SSD1306 0.96in OLED | B6: On, typical watch face | C6: 12 | D6: Module-level estimate incl. charge pump. Full white about 25 mA, mostly dark face about 7 mA.
A7: SSD1306 0.96in OLED | B7: Display off (sleep command) | C7: 0.01 | D7: Panel asleep; module leaks a little.
A8: MPU-6050 | B8: Accel + gyro, normal mode | C8: 3.9 | D8: Datasheet. Today's firmware leaves it running.
A9: MPU-6050 | B9: Sleep | C9: 0.005 | D9: Datasheet, about 5 uA.
A10: MAX30102 | B10: Measuring, IR + red | C10: 6 | D10: Datasheet; LED current dominates.
A11: MAX30102 | B11: Shutdown | C11: 0.0007 | D11: Datasheet, 0.7 uA.
A12: Whole board (planned) | B12: Optimised idle, light sleep + BLE - low | C12: 1 | D12: REFERENCE-PRODUCT section 4: modelled 'optimised idle' 1-3 mA. PLANNED firmware, not built.
A13: Whole board (planned) | B13: Optimised idle, light sleep + BLE - high | C13: 3 | D13: As above, upper end.
A15: Seeed's published XIAO figures (board alone, for comparison)
B16: Active | C16: below 75 mA | D16: https://wiki.seeedstudio.com/XIAO_ESP32C3_Getting_Started/
B17: Modem-sleep | C17: below 25 mA | D17: https://wiki.seeedstudio.com/XIAO_ESP32C3_Getting_Started/
B18: Light sleep | C18: below 4 mA | D18: https://wiki.seeedstudio.com/XIAO_ESP32C3_Getting_Started/
B19: Deep sleep | C19: about 43-44 uA | D19: https://wiki.seeedstudio.com/XIAO_ESP32C3_Getting_Started/

Sheet Runtime
A1: Battery life model (modelled currents, not measured)
A3: Battery capacity (mAh) | B3: 300 | C3: Protected LiPo, 30 x 12 x 4 mm (fitted cell)
A4: Usable fraction | B4: 0.8 | C4: Assumption: do not run a LiPo flat; it also loses capacity with age.
A5: Usable capacity (mAh) | B5: =B3*B4 -> 240
A7: Planned usage profile (author's power model)
A8: Screen wakes per day | B8: 50
A9: Seconds on per wake | B9: 30
A10: Heart-rate readings per day | B10: 5
A11: Seconds per reading | B11: 30
A12: Screen-on hours per day | B12: =B8*B9/3600 -> 0.41666667 | C12: Screen times out after 30 s (planned: today's firmware is always on).
A13: Heart-rate hours per day | B13: =B10*B11/3600 -> 0.041666667
A15: State | B15: Current (mA) | C15: What is running
A16: S1 Screen on, CPU active, WiFi off | B16: ='Power Budget'!C2+'Power Budget'!C6+'Power Budget'!C8 -> 37.9 | C16: Today's firmware after switch-on: display on, loop running, MPU-6050 running. MAX30102 shut down.
A17: S2 Screen on, WiFi connected | B17: ='Power Budget'!C3+'Power Budget'!C6+'Power Budget'!C8 -> 35.9 | C17: The model's 'screen on' figure (~36 mA). Conservative for the planned profile, since WiFi is off after boot.
A18: S3 Heart-rate measurement | B18: ='Power Budget'!C2+'Power Budget'!C6+'Power Budget'!C10+'Power Budget'!C8 -> 43.9 | C18: LEDs on, screen showing the reading, MPU still running (no motion check).
A19: S4 WiFi sync burst | B19: ='Power Budget'!C4+'Power Budget'!C7+'Power Budget'!C9+'Power Budget'!C11 -> 100.0157 | C19: Time + weather fetch at switch-on. Seconds, once.
A20: S5 Planned sleep, low | B20: ='Power Budget'!C12 -> 1 | C20: Planned light sleep + BLE, best case. Not in today's firmware.
A21: S6 Planned sleep, high | B21: ='Power Budget'!C13 -> 3 | C21: Planned light sleep + BLE, worst case. Not in today's firmware.
A22: S7 Deep sleep (illustration) | B22: ='Power Budget'!C5+'Power Budget'!C7+'Power Budget'!C9+'Power Budget'!C11 -> 0.0587 | C22: XIAO deep sleep with every module asleep. Illustration only: esp_watch has no sleep mode.
A24: Scenarios - hours per day in each state (blue = edit; black = rest of the day)
A25: Scenario | B25: S1 scr+CPU | C25: S2 scr+WiFi | D25: S3 HR | E25: S4 WiFi burst | F25: S5 sleep lo | G25: S6 sleep hi | H25: S7 deep | I25: Check (h) | J25: Note
A26: A. Today's firmware, always on | B26: =24-(C26+D26+E26+F26+G26+H26) -> 23.99 | C26: 0 | D26: 0 | E26: 0.01 | F26: 0 | G26: 0 | H26: 0 | I26: =SUM(B26:H26) -> 24 | J26: Switch-on WiFi burst (~36 s), then screen and loop on all day.
A27: B. Planned profile, sleep low (1 mA) | B27: 0 | C27: =$B$12 -> 0.41666667 | D27: =$B$13 -> 0.041666667 | E27: 0 | F27: =24-(B27+C27+D27+E27+G27+H27) -> 23.541667 | G27: 0 | H27: 0 | I27: =SUM(B27:H27) -> 24 | J27: A0 / B3 worked example, best case. Screen-on uses the conservative S2 figure.
A28: C. Planned profile, sleep high (3 mA) | B28: 0 | C28: =$B$12 -> 0.41666667 | D28: =$B$13 -> 0.041666667 | E28: 0 | F28: 0 | G28: =24-(B28+C28+D28+E28+F28+H28) -> 23.541667 | H28: 0 | I28: =SUM(B28:H28) -> 24 | J28: Same, worst case.
A29: D. Planned profile + deep sleep (illustration) | B29: 0 | C29: =$B$12 -> 0.41666667 | D29: =$B$13 -> 0.041666667 | E29: 0 | F29: 0 | G29: 0 | H29: =24-(B29+C29+D29+E29+F29+G29) -> 23.541667 | I29: =SUM(B29:H29) -> 24 | J29: Shows the ceiling if the watch deep-slept between uses. Wake-up costs not modelled.
A30: E. Heart rate measured continuously | B30: 0 | C30: 0 | D30: =24-(B30+C30+E30+F30+G30+H30) -> 24 | E30: 0 | F30: 0 | G30: 0 | H30: 0 | I30: =SUM(B30:H30) -> 24 | J30: B3 Case 1.
A32: Results
A33: Scenario | B33: Avg current (mA) | C33: Charge per day (mAh) | D33: Runtime (hours) | E33: Runtime (days)
A34: =A26 -> A. Today's firmware, always on | B34: =C34/24 -> 37.925882 | C34: =B26*$B$16+C26*$B$17+D26*$B$18+E26*$B$19+F26*$B$20+G26*$B$21+H26*$B$22 -> 910.22116 | D34: =IF(C34=0,"",$B$5/C34*24) -> 6.3281324 | E34: =IF(C34=0,"",$B$5/C34) -> 0.26367218
A35: =A27 -> B. Planned profile, sleep low (1 mA) | B35: =C35/24 -> 1.6803819 | C35: =B27*$B$16+C27*$B$17+D27*$B$18+E27*$B$19+F27*$B$20+G27*$B$21+H27*$B$22 -> 40.329167 | D35: =IF(C35=0,"",$B$5/C35*24) -> 142.82467 | E35: =IF(C35=0,"",$B$5/C35) -> 5.951028
A36: =A28 -> C. Planned profile, sleep high (3 mA) | B36: =C36/24 -> 3.6421875 | C36: =B28*$B$16+C28*$B$17+D28*$B$18+E28*$B$19+F28*$B$20+G28*$B$21+H28*$B$22 -> 87.4125 | D36: =IF(C36=0,"",$B$5/C36*24) -> 65.894466 | E36: =IF(C36=0,"",$B$5/C36) -> 2.7456027
A37: =A29 -> D. Planned profile + deep sleep (illustration) | B37: =C37/24 -> 0.75705816 | C37: =B29*$B$16+C29*$B$17+D29*$B$18+E29*$B$19+F29*$B$20+G29*$B$21+H29*$B$22 -> 18.169396 | D37: =IF(C37=0,"",$B$5/C37*24) -> 317.01659 | E37: =IF(C37=0,"",$B$5/C37) -> 13.209025
A38: =A30 -> E. Heart rate measured continuously | B38: =C38/24 -> 43.9 | C38: =B30*$B$16+C30*$B$17+D30*$B$18+E30*$B$19+F30*$B$20+G30*$B$21+H30*$B$22 -> 1053.6 | D38: =IF(C38=0,"",$B$5/C38*24) -> 5.4669704 | E38: =IF(C38=0,"",$B$5/C38) -> 0.22779043
A40: Cell comparison - planned profile (days)
A41: Cell | B41: Rated mAh | C41: Usable mAh | D41: Days, sleep low | E41: Days, sleep high
A42: 301235 (earlier candidate) | B42: 100 | C42: =B42*$B$4 -> 80 | D42: =IF($C$35=0,"",C42/$C$35) -> 1.983676 | E42: =IF($C$36=0,"",C42/$C$36) -> 0.91520092
A43: 401235 (earlier candidate) | B43: 150 | C43: =B43*$B$4 -> 120 | D43: =IF($C$35=0,"",C43/$C$35) -> 2.975514 | E43: =IF($C$36=0,"",C43/$C$36) -> 1.3728014
A44: 501235 (earlier candidate) | B44: 200 | C44: =B44*$B$4 -> 160 | D44: =IF($C$35=0,"",C44/$C$35) -> 3.967352 | E44: =IF($C$36=0,"",C44/$C$36) -> 1.8304018
A45: Fitted cell, 30 x 12 x 4 mm | B45: =$B$3 -> 300 | C45: =B45*$B$4 -> 240 | D45: =IF($C$35=0,"",C45/$C$35) -> 5.951028 | E45: =IF($C$36=0,"",C45/$C$36) -> 2.7456027
A47: Notes
...
